Workbook

Sheet 工作表1
B2: 病例個數 | C2: 143
B3: 圖總數 | C3: 2067
D6: 分級 | E6: 病例數 | F6: 圖片數量
D7: Normal | E7: 67 | F7: 1258
D8: Dysplasia | E8: 47 | F8: 441
D9: SCC | E9: 29 | F9: 368
D10: Total | E10: =SUM(E7:E9) -> 143 | F10: =SUM(F7:F9) -> 2067
G12: 資料集 | H12: 2067張 | J12: 訓練集 | K12: 1447張 | M12: 驗證集 | N12: 620張
G13: 類別 | H13: 框數 | J13: 類別 | K13: 框數 | M13: 類別 | N13: 框數
G14: Dysplasia | H14: 1360 | J14: Dysplasia | K14: 899 | M14: Dysplasia | N14: 461
G15: SCC | H15: 230 | J15: SCC | K15: 157 | M15: SCC | N15: 73
G16: 出血 | H16: 384 | J16: 出血 | K16: 262 | M16: 出血 | N16: 122
G17: 發炎 | H17: 132 | J17: 發炎 | K17: 113 | M17: 發炎 | N17: 19
G18: 通道 | H18: 1296 | J18: 通道 | K18: 901 | M18: 通道 | N18: 395
G19: 賁門 | H19: 334 | J19: 賁門 | K19: 235 | M19: 賁門 | N19: 99
G20: 異物 | H20: 1419 | J20: 異物 | K20: 961 | M20: 異物 | N20: 458
G21: 器械 | H21: 53 | J21: 器械 | K21: 37 | M21: 器械 | N21: 16
G22: 人造資訊 | H22: 751 | J22: 人造資訊 | K22: 536 | M22: 人造資訊 | N22: 215
G23: 氣泡 | H23: 1494 | J23: 氣泡 | K23: 1067 | M23: 氣泡 | N23: 427
G24: 反光 | H24: 4666 | J24: 反光 | K24: 3292 | M24: 反光 | N24: 1374
G25: Total | H25: =SUM(H14:H24) -> 12119 | J25: Total | K25: 8460 | M25: Total | N25: =SUM(N14:N24) -> 3659

Sheet 框選統計
E6: 資料集 | F6: 2067張 | H6: WLI-1554 | I6: 1860張 | K6: 1554 | L6: 0.3 | N6: WLI-1554 | O6: 0.7
E7: 全部 | F7: 框數 | H7: 訓練集90% | I7: 框數 | K7: 表格輸出 | L7: 框數 | N7: 訓練集 | O7: 框數
E8: Dysplasia | F8: 1360 | H8: Dysplasia | I8: 1189 | K8: Dysplasia | L8: 461 | N8: Dysplasia | O8: =F8-L8 -> 899
E9: SCC | F9: 230 | H9: SCC | I9: 208 | K9: SCC | L9: 73 | N9: SCC | O9: =F9-L9 -> 157
E10: 出血 | F10: 384 | H10: 出血 | I10: 348 | K10: 出血 | L10: 122 | N10: 出血 | O10: =F10-L10 -> 262
E11: 發炎 | F11: 132 | H11: 發炎 | I11: 121 | K11: 發炎 | L11: 19 | N11: 發炎 | O11: =F11-L11 -> 113
E12: 通道 | F12: 1296 | H12: 通道 | I12: 1159 | K12: 通道 | L12: 395 | N12: 通道 | O12: =F12-L12 -> 901
E13: 賁門 | F13: 334 | H13: 賁門 | I13: 303 | K13: 賁門 | L13: 99 | N13: 賁門 | O13: =F13-L13 -> 235
E14: 異物 | F14: 1419 | H14: 異物 | I14: 1280 | K14: 異物 | L14: 458 | N14: 異物 | O14: =F14-L14 -> 961
E15: 器械 | F15: 53 | H15: 器械 | I15: 47 | K15: 器械 | L15: 16 | N15: 器械 | O15: =F15-L15 -> 37
E16: 人造資訊 | F16: 751 | H16: 人造資訊 | I16: 656 | K16: 人造資訊 | L16: 215 | N16: 人造資訊 | O16: =F16-L16 -> 536
E17: 氣泡 | F17: 1494 | H17: 氣泡 | I17: 1370 | K17: 氣泡 | L17: 427 | N17: 氣泡 | O17: =F17-L17 -> 1067
E18: 反光 | F18: 4666 | H18: 反光 | I18: 4196 | K18: 反光 | L18: 1374 | N18: 反光 | O18: =F18-L18 -> 3292
E19: Total | F19: =SUM(F8:F18) -> 12119 | H19: Total | I19: =SUM(I8:I18) -> 10877 | K19: Total | L19: =SUM(L8:L18) -> 3659 | N19: Total | O19: =SUM(O8:O18) -> 8460
E23: WLI-1554 | F23: 413張 | H23: WLI-1554 | I23: 517張 | K23: WLI-1554 | L23: 620張
E24: 測試集20% | F24: 框數 | H24: 測試集25% | I24: 框數 | K24: 測試集30% | L24: 框數
E25: Dysplasia | F25: 246 | H25: Dysplasia | I25: 399 | K25: Dysplasia | L25: 461
E26: SCC | F26: 37 | H26: SCC | I26: 57 | K26: SCC | L26: 73
E27: 出血 | F27: 74 | H27: 出血 | I27: 99 | K27: 出血 | L27: 122
E28: 發炎 | F28: 22 | H28: 發炎 | I28: 17 | K28: 發炎 | L28: 19
E29: 通道 | F29: 231 | H29: 通道 | I29: 332 | K29: 通道 | L29: 395
E30: 賁門 | F30: 85 | H30: 賁門 | I30: 84 | K30: 賁門 | L30: 99
E31: 異物 | F31: 271 | H31: 異物 | I31: 386 | K31: 異物 | L31: 458
E32: 器械 | F32: 11 | H32: 器械 | I32: 13 | K32: 器械 | L32: 16
E33: 人造資訊 | F33: 137 | H33: 人造資訊 | I33: 189 | K33: 人造資訊 | L33: 215
E34: 氣泡 | F34: 339 | H34: 氣泡 | I34: 359 | K34: 氣泡 | L34: 427
E35: 反光 | F35: 945 | H35: 反光 | I35: 1174 | K35: 反光 | L35: 1374
E36: Total | F36: =SUM(F25:F35) -> 2398 | H36: Total | I36: =SUM(I25:I35) -> 3109 | K36: Total | L36: =SUM(L25:L35) -> 3659
K40: WLI-2023 | L40: 620張
K41: 測試集30% | L41: 框數
K42: Dysplasia | L42: 363
K43: SCC | L43: 65
K44: 出血 | L44: 120
K45: 發炎 | L45: 39
K46: 通道 | L46: 356
K47: 賁門 | L47: 127
K48: 異物 | L48: 431
K49: 器械 | L49: 14
K50: 人造資訊 | L50: 222
K51: 氣泡 | L51: 486
...

Sheet WLI
B5: WLI_比例 | R5: WLI_個數
B6: True Predicted | C6: Dysplasia | D6: SCC | E6: 出血 | F6: 發炎 | G6: 通道 | H6: 賁門 | I6: 異物 | J6: 器械 | K6: 人造資訊 | L6: 氣泡 | M6: 反光 | N6: Background | O6: Predicted all | R6: True Predicted | S6: Dysplasia | T6: SCC | U6: 出血 | V6: 發炎 | W6: 通道 | X6: 賁門 | Y6: 異物 | Z6: 器械 | AA6: 人造資訊 | AB6: 氣泡 | AC6: 反光 | AD6: Background | AE6: Predicted all
B7: Dysplasia | C7: 0.785 | N7: 0.12 | O7: =$P7 -> 0.905 | P7: =SUM($C7:$N7) -> 0.905 | R7: Dysplasia | S7: =ROUND(C7*框選統計!$L$8,0) -> 362 | T7: =ROUND(D7*框選統計!$L$9,0) -> 0 | U7: =ROUND(E7*框選統計!$L$10,0) -> 0 | V7: =ROUND(F7*框選統計!$L$11,0) -> 0 | W7: =ROUND(G7*框選統計!$L$12,0) -> 0 | X7: =ROUND(H7*框選統計!$L$13,0) -> 0 | Y7: =ROUND(I7*框選統計!$L$14,0) -> 0 | Z7: =ROUND(J7*框選統計!$L$15,0) -> 0 | AA7: =ROUND(K7*框選統計!$L$16,0) -> 0 | AB7: =ROUND(L7*框選統計!$L$17,0) -> 0 | AC7: =ROUND(M7*框選統計!$L$18,0) -> 0 | AD7: =ROUND(N7*框選統計!$L8,0) -> 55 | AE7: =$AF7 -> 417 | AF7: =SUM($S7:$AD7) -> 417
B8: SCC | D8: 0.86 | N8: 0.01 | O8: =$P8 -> 0.87 | P8: =SUM($C8:$N8) -> 0.87 | R8: SCC | S8: =ROUND(C8*框選統計!$L$8,0) -> 0 | T8: =ROUND(D8*框選統計!$L$9,0) -> 63 | U8: =ROUND(E8*框選統計!$L$10,0) -> 0 | V8: =ROUND(F8*框選統計!$L$11,0) -> 0 | W8: =ROUND(G8*框選統計!$L$12,0) -> 0 | X8: =ROUND(H8*框選統計!$L$13,0) -> 0 | Y8: =ROUND(I8*框選統計!$L$14,0) -> 0 | Z8: =ROUND(J8*框選統計!$L$15,0) -> 0 | AA8: =ROUND(K8*框選統計!$L$16,0) -> 0 | AB8: =ROUND(L8*框選統計!$L$17,0) -> 0 | AC8: =ROUND(M8*框選統計!$L$18,0) -> 0 | AD8: =ROUND(N8*框選統計!$L9,0) -> 1 | AE8: =$AF8 -> 64 | AF8: =SUM($S8:$AD8) -> 64
B9: 出血 | E9: 0.89 | F9: 0.05 | N9: 0.05 | O9: =$P9 -> 0.99 | P9: =SUM($C9:$N9) -> 0.99 | R9: 出血 | S9: =ROUND(C9*框選統計!$L$8,0) -> 0 | T9: =ROUND(D9*框選統計!$L$9,0) -> 0 | U9: =ROUND(E9*框選統計!$L$10,0) -> 109 | V9: =ROUND(F9*框選統計!$L$11,0) -> 1 | W9: =ROUND(G9*框選統計!$L$12,0) -> 0 | X9: =ROUND(H9*框選統計!$L$13,0) -> 0 | Y9: =ROUND(I9*框選統計!$L$14,0) -> 0 | Z9: =ROUND(J9*框選統計!$L$15,0) -> 0 | AA9: =ROUND(K9*框選統計!$L$16,0) -> 0 | AB9: =ROUND(L9*框選統計!$L$17,0) -> 0 | AC9: =ROUND(M9*框選統計!$L$18,0) -> 0 | AD9: =ROUND(N9*框選統計!$L10,0) -> 6 | AE9: =$AF9 -> 116 | AF9: =SUM($S9:$AD9) -> 116
B10: 發炎 | F10: 0.53 | N10: 0.01 | O10: =$P10 -> 0.54 | P10: =SUM($C10:$N10) -> 0.54 | R10: 發炎 | S10: =ROUND(C10*框選統計!$L$8,0) -> 0 | T10: =ROUND(D10*框選統計!$L$9,0) -> 0 | U10: =ROUND(E10*框選統計!$L$10,0) -> 0 | V10: =ROUND(F10*框選統計!$L$11,0) -> 10 | W10: =ROUND(G10*框選統計!$L$12,0) -> 0 | X10: =ROUND(H10*框選統計!$L$13,0) -> 0 | Y10: =ROUND(I10*框選統計!$L$14,0) -> 0 | Z10: =ROUND(J10*框選統計!$L$15,0) -> 0 | AA10: =ROUND(K10*框選統計!$L$16,0) -> 0 | AB10: =ROUND(L10*框選統計!$L$17,0) -> 0 | AC10: =ROUND(M10*框選統計!$L$18,0) -> 0 | AD10: =ROUND(N10*框選統計!$L11,0) -> 0 | AE10: =$AF10 -> 10 | AF10: =SUM($S10:$AD10) -> 10
B11: 通道 | G11: 0.94 | N11: 0.03 | O11: =$P11 -> 0.97 | P11: =SUM($C11:$N11) -> 0.97 | R11: 通道 | S11: =ROUND(C11*框選統計!$L$8,0) -> 0 | T11: =ROUND(D11*框選統計!$L$9,0) -> 0 | U11: =ROUND(E11*框選統計!$L$10,0) -> 0 | V11: =ROUND(F11*框選統計!$L$11,0) -> 0 | W11: =ROUND(G11*框選統計!$L$12,0) -> 371 | X11: =ROUND(H11*框選統計!$L$13,0) -> 0 | Y11: =ROUND(I11*框選統計!$L$14,0) -> 0 | Z11: =ROUND(J11*框選統計!$L$15,0) -> 0 | AA11: =ROUND(K11*框選統計!$L$16,0) -> 0 | AB11: =ROUND(L11*框選統計!$L$17,0) -> 0 | AC11: =ROUND(M11*框選統計!$L$18,0) -> 0 | AD11: =ROUND(N11*框選統計!$L12,0) -> 12 | AE11: =$AF11 -> 383 | AF11: =SUM($S11:$AD11) -> 383
B12: 賁門 | H12: 0.95 | N12: 0.01 | O12: =$P12 -> 0.96 | P12: =SUM($C12:$N12) -> 0.96 | R12: 賁門 | S12: =ROUND(C12*框選統計!$L$8,0) -> 0 | T12: =ROUND(D12*框選統計!$L$9,0) -> 0 | U12: =ROUND(E12*框選統計!$L$10,0) -> 0 | V12: =ROUND(F12*框選統計!$L$11,0) -> 0 | W12: =ROUND(G12*框選統計!$L$12,0) -> 0 | X12: =ROUND(H12*框選統計!$L$13,0) -> 94 | Y12: =ROUND(I12*框選統計!$L$14,0) -> 0 | Z12: =ROUND(J12*框選統計!$L$15,0) -> 0 | AA12: =ROUND(K12*框選統計!$L$16,0) -> 0 | AB12: =ROUND(L12*框選統計!$L$17,0) -> 0 | AC12: =ROUND(M12*框選統計!$L$18,0) -> 0 | AD12: =ROUND(N12*框選統計!$L13,0) -> 1 | AE12: =$AF12 -> 95 | AF12: =SUM($S12:$AD12) -> 95
B13: 異物 | I13: 0.815 | N13: 0.13 | O13: =$P13 -> 0.945 | P13: =SUM($C13:$N13) -> 0.945 | R13: 異物 | S13: =ROUND(C13*框選統計!$L$8,0) -> 0 | T13: =ROUND(D13*框選統計!$L$9,0) -> 0 | U13: =ROUND(E13*框選統計!$L$10,0) -> 0 | V13: =ROUND(F13*框選統計!$L$11,0) -> 0 | W13: =ROUND(G13*框選統計!$L$12,0) -> 0 | X13: =ROUND(H13*框選統計!$L$13,0) -> 0 | Y13: =ROUND(I13*框選統計!$L$14,0) -> 373 | Z13: =ROUND(J13*框選統計!$L$15,0) -> 0 | AA13: =ROUND(K13*框選統計!$L$16,0) -> 0 | AB13: =ROUND(L13*框選統計!$L$17,0) -> 0 | AC13: =ROUND(M13*框選統計!$L$18,0) -> 0 | AD13: =ROUND(N13*框選統計!$L14,0) -> 60 | AE13: =$AF13 -> 433 | AF13: =SUM($S13:$AD13) -> 433
B14: 器械 | J14: 1 | N14: 0 | O14: =$P14 -> 1 | P14: =SUM($C14:$N14) -> 1 | R14: 器械 | S14: =ROUND(C14*框選統計!$L$8,0) -> 0 | T14: =ROUND(D14*框選統計!$L$9,0) -> 0 | U14: =ROUND(E14*框選統計!$L$10,0) -> 0 | V14: =ROUND(F14*框選統計!$L$11,0) -> 0 | W14: =ROUND(G14*框選統計!$L$12,0) -> 0 | X14: =ROUND(H14*框選統計!$L$13,0) -> 0 | Y14: =ROUND(I14*框選統計!$L$14,0) -> 0 | Z14: =ROUND(J14*框選統計!$L$15,0) -> 16 | AA14: =ROUND(K14*框選統計!$L$16,0) -> 0 | AB14: =ROUND(L14*框選統計!$L$17,0) -> 0 | AC14: =ROUND(M14*框選統計!$L$18,0) -> 0 | AD14: =ROUND(N14*框選統計!$L15,0) -> 0 | AE14: =$AF14 -> 16 | AF14: =SUM($S14:$AD14) -> 16
B15: 人造資訊 | K15: 0.98 | N15: 0.04 | O15: =$P15 -> 1.02 | P15: =SUM($C15:$N15) -> 1.02 | R15: 人造資訊 | S15: =ROUND(C15*框選統計!$L$8,0) -> 0 | T15: =ROUND(D15*框選統計!$L$9,0) -> 0 | U15: =ROUND(E15*框選統計!$L$10,0) -> 0 | V15: =ROUND(F15*框選統計!$L$11,0) -> 0 | W15: =ROUND(G15*框選統計!$L$12,0) -> 0 | X15: =ROUND(H15*框選統計!$L$13,0) -> 0 | Y15: =ROUND(I15*框選統計!$L$14,0) -> 0 | Z15: =ROUND(J15*框選統計!$L$15,0) -> 0 | AA15: =ROUND(K15*框選統計!$L$16,0) -> 211 | AB15: =ROUND(L15*框選統計!$L$17,0) -> 0 | AC15: =ROUND(M15*框選統計!$L$18,0) -> 0 | AD15: =ROUND(N15*框選統計!$L16,0) -> 9 | AE15: =$AF15 -> 220 | AF15: =SUM($S15:$AD15) -> 220
B16: 氣泡 | L16: 0.84 | N16: 0.12 | O16: =$P16 -> 0.96 | P16: =SUM($C16:$N16) -> 0.96 | R16: 氣泡 | S16: =ROUND(C16*框選統計!$L$8,0) -> 0 | T16: =ROUND(D16*框選統計!$L$9,0) -> 0 | U16: =ROUND(E16*框選統計!$L$10,0) -> 0 | V16: =ROUND(F16*框選統計!$L$11,0) -> 0 | W16: =ROUND(G16*框選統計!$L$12,0) -> 0 | X16: =ROUND(H16*框選統計!$L$13,0) -> 0 | Y16: =ROUND(I16*框選統計!$L$14,0) -> 0 | Z16: =ROUND(J16*框選統計!$L$15,0) -> 0 | AA16: =ROUND(K16*框選統計!$L$16,0) -> 0 | AB16: =ROUND(L16*框選統計!$L$17,0) -> 359 | AC16: =ROUND(M16*框選統計!$L$18,0) -> 0 | AD16: =ROUND(N16*框選統計!$L17,0) -> 51 | AE16: =$AF16 -> 410 | AF16: =SUM($S16:$AD16) -> 410
B17: 反光 | L17: 0.03 | M17: 0.82 | N17: 0.48 | O17: =$P17 -> 1.33 | P17: =SUM($C17:$N17) -> 1.33 | R17: 反光 | S17: =ROUND(C17*框選統計!$L$8,0) -> 0 | T17: =ROUND(D17*框選統計!$L$9,0) -> 0 | U17: =ROUND(E17*框選統計!$L$10,0) -> 0 | V17: =ROUND(F17*框選統計!$L$11,0) -> 0 | W17: =ROUND(G17*框選統計!$L$12,0) -> 0 | X17: =ROUND(H17*框選統計!$L$13,0) -> 0 | Y17: =ROUND(I17*框選統計!$L$14,0) -> 0 | Z17: =ROUND(J17*框選統計!$L$15,0) -> 0 | AA17: =ROUND(K17*框選統計!$L$16,0) -> 0 | AB17: =ROUND(L17*框選統計!$L$17,0) -> 13 | AC17: =ROUND(M17*框選統計!$L$18,0) -> 1127 | AD17: =ROUND(N17*框選統計!$L18,0) -> 660 | AE17: =$AF17 -> 1800 | AF17: =SUM($S17:$AD17) -> 1800
B18: Background | C18: 0.215 | D18: 0.14 | E18: 0.11 | F18: 0.42 | G18: 0.06 | H18: 0.05 | I18: 0.185 | J18: 0 | K18: 0.02 | L18: 0.13 | M18: 0.18 | N18: 0 | O18: =$P18 -> 1.51 | P18: =SUM($C18:$N18) -> 1.51 | R18: Background | S18: =ROUND(C18*框選統計!$L$8,0) -> 99 | T18: =ROUND(D18*框選統計!$L$9,0) -> 10 | U18: =ROUND(E18*框選統計!$L$10,0) -> 13 | V18: =ROUND(F18*框選統計!$L$11,0) -> 8 | W18: =ROUND(G18*框選統計!$L$12,0) -> 24 | X18: =ROUND(H18*框選統計!$L$13,0) -> 5 | Y18: =ROUND(I18*框選統計!$L$14,0) -> 85 | Z18: =ROUND(J18*框選統計!$L$15,0) -> 0 | AA18: =ROUND(K18*框選統計!$L$16,0) -> 4 | AB18: =ROUND(L18*框選統計!$L$17,0) -> 56 | AC18: =ROUND(M18*框選統計!$L$18,0) -> 247 | AD18: =ROUND(N18*框選統計!$L19,0) -> 0 | AE18: =$AF18 -> 551 | AF18: =SUM($S18:$AD18) -> 551
B19: True all | C19: =C$20 -> 1 | D19: =D$20 -> 1 | E19: =E$20 -> 1 | F19: =F$20 -> 1 | G19: =G$20 -> 1 | H19: =H$20 -> 1 | I19: =I$20 -> 1 | J19: =J$20 -> 1 | ... N19: =N$20 -> 1 | P19: =SUM(P7:P18) -> 12 | R19: True all | S19: =S$20 -> 461 | T19: =T$20 -> 73 | U19: =U$20 -> 122 | V19: =V$20 -> 19 | W19: =W$20 -> 395 | X19: =X$20 -> 99 | Y19: =Y$20 -> 458 | Z19: =Z$20 -> 16 | ... AD19: =AD$20 -> 855 | AE19: =IF(AE20=AF19,AE20,"no") -> 4515 | AF19: =SUM(AF7:AF18) -> 4515
C20: =SUM(C$7:C$18) -> 1 | D20: =SUM(D$7:D$18) -> 1 | E20: =SUM(E$7:E$18) -> 1 | F20: =SUM(F$7:F$18) -> 1 | G20: =SUM(G$7:G$18) -> 1 | H20: =SUM(H$7:H$18) -> 1 | I20: =SUM(I$7:I$18) -> 1 | J20: =SUM(J$7:J$18) -> 1 | ... N20: =SUM(N$7:N$18) -> 1 | O20: =SUM(C20:N20) -> 12 | S20: =SUM(S$7:S$18) -> 461 | T20: =SUM(T$7:T$18) -> 73 | U20: =SUM(U$7:U$18) -> 122 | V20: =SUM(V$7:V$18) -> 19 | W20: =SUM(W$7:W$18) -> 395 | X20: =SUM(X$7:X$18) -> 99 | Y20: =SUM(Y$7:Y$18) -> 458 | Z20: =SUM(Z$7:Z$18) -> 16 | ... AD20: =SUM(AD$7:AD$18) -> 855 | AE20: =SUM(S20:AD20) -> 4515
AE21: =SUM(S20:AC20) -> 3660
AD22: others
B23: 結果 | D23: AP | E23: Sensitivity | F23: Precision | G23: F1-score | H23: accuracy | I23: Kappa | J23: Specificity | R23: Specificity | S23: =((T8+U9+V10+W11+X12+Y13+Z14+AA15+AB16+AC17)/(T19+U19+V19+W19+X19+Y19+Z19+AA19+AB19+AC19)) -> 0.85432948 | T23: =((S7+U9+V10+W11+X12+Y13+Z14+AA15+AB16+AC17)/(S19+U19+V19+W19+X19+Y19+Z19+AA19+AB19+AC19)) -> 0.8452746 | U23: =((T8+S7+V10+W11+X12+Y13+Z14+AA15+AB16+AC17)/(T19+S19+V19+W19+X19+Y19+Z19+AA19+AB19+AC19)) -> 0.84397965 | V23: =((T8+U9+S7+W11+X12+Y13+Z14+AA15+AB16+AC17)/(T19+U19+S19+W19+X19+Y19+Z19+AA19+AB19+AC19)) -> 0.8472947 | W23: =((T8+U9+V10+S7+X12+Y13+Z14+AA15+AB16+AC17)/(T19+U19+V19+S19+X19+Y19+Z19+AA19+AB19+AC19)) -> 0.83430322 | X23: =((T8+U9+V10+W11+S7+Y13+Z14+AA15+AB16+AC17)/(T19+U19+V19+W19+S19+Y19+Z19+AA19+AB19+AC19)) -> 0.8427408 | Y23: =((T8+U9+V10+W11+X12+S7+Z14+AA15+AB16+AC17)/(T19+U19+V19+W19+X19+S19+Z19+AA19+AB19+AC19)) -> 0.85009369 | Z23: =((T8+U9+V10+W11+X12+Y13+S7+AA15+AB16+AC17)/(T19+U19+V19+W19+X19+Y19+S19+AA19+AB19+AC19)) -> 0.8449506 | AA23: =((T8+U9+V10+W11+X12+Y13+Z14+S7+AB16+AC17)/(T19+U19+V19+W19+X19+Y19+Z19+S19+AB19+AC19)) -> 0.8371553 | AB23: =((T8+U9+V10+W11+X12+Y13+Z14+AA15+S7+AC17)/(T19+U19+V19+W19+X19+Y19+Z19+AA19+S19+AC19)) -> 0.84653465 | AC23: =((T8+U9+V10+W11+X12+Y13+Z14+AA15+AB16+S7)/(T19+U19+V19+W19+X19+Y19+Z19+AA19+AB19+S19)) -> 0.86089239
B24: RGB-WLI | C24: Dysplasia | D24: =ROUND(S$29,2) -> 0.79 | E24: =ROUND($S$24, 2) -> 0.79 | F24: =ROUND($S$25, 2) -> 0.87 | G24: =ROUND($S$27, 2) -> 0.82 | H24: =ROUND($S$26, 2) -> 0.85 | I24: =ROUND($S$28, 2) -> 0.8 | J24: =ROUND(S23, 2) -> 0.85 | M24: kappa | N24: pe | O24: po | R24: Sensitivity | S24: =(S7/S$19) -> 0.78524946 | T24: =(T8/T$19) -> 0.8630137 | U24: =(U9/U$19) -> 0.89344262 | V24: =(V10/V$19) -> 0.52631579 | W24: =(W11/W$19) -> 0.93924051 | X24: =(X12/X$19) -> 0.94949495 | Y24: =(Y13/Y$19) -> 0.81441048 | Z24: =(Z14/Z$19) -> 1 | AA24: =(AA15/AA$19) -> 0.98139535 | AB24: =(AB16/AB$19) -> 0.83878505 | AC24: =(AC17/AC$19) -> 0.8202329 | AD24: =((V10+W11+X12+Y13+Z14+AA15+AB16+AC17)/(V19+W19+X19+Y19+Z19+AA19+AB19+AC19)) -> 0.85252996
C25: SCC | D25: =ROUND(T$29,2) -> 0.88 | E25: =ROUND($T$24, 2) -> 0.86 | F25: =ROUND($T$25, 2) -> 0.98 | G25: =ROUND($T$27, 2) -> 0.92 | J25: =ROUND(T23, 2) -> 0.85 | M25: =(($O$25-$N$25)/(1-$N$25)) -> 0.79611551 | N25: =(($S$19*$AE$7+$T$19*$AE$8+$U$19*$AE$9+$V$19*$AE$10+$W$19*$AE$11+$X$19*$AE$12+$Y$19*$AE$13+$Z$19*$AE$14+$AA$19*$AE$15+$AB$19*$AE$16+$AC$19*$AE$17)/(框選統計!L19*框選統計!L19)) -> 0.24398136 | O25: =(($S$7+$T$8+$U$9+$V$10+$W$11+$X$12+$Y$13+$Z$14+$AA$15+$AB$16+$AC$17)/(框選統計!L19)) -> 0.84585952 | R25: Precision | S25: =(S7/$AE7) -> 0.86810552 | T25: =(T8/$AE8) -> 0.984375 | U25: =(U9/$AE9) -> 0.93965517 | V25: =(V10/$AE10) -> 1 | W25: =(W11/$AE11) -> 0.96866841 | X25: =(X12/$AE12) -> 0.98947368 | Y25: =(Y13/$AE13) -> 0.86143187 | Z25: =(Z14/$AE14) -> 1 | AA25: =(AA15/$AE15) -> 0.95909091 | AB25: =(AB16/$AE16) -> 0.87560976 | AC25: =(AC17/$AE17) -> 0.62611111 | AD25: =((V10+W11+X12+Y13+Z14+AA15+AB16+AC17)/(AE10+AE11+AE12+AE13+AE14+AE15+AE16+AE17)) -> 0.76061776
C26: 出血 | D26: =ROUND(U$29,2) -> 0.84 | E26: =ROUND($U$24, 2) -> 0.89 | F26: =ROUND($U$25, 2) -> 0.94 | G26: =ROUND($U$27, 2) -> 0.92 | J26: =ROUND(U23, 2) -> 0.84 | R26: Accuracy | S26: =((S7+T8+U9+V10+W11+X12+Y13+Z14+AA15+AB16+AC17)/(框選統計!L19)) -> 0.84585952
C27: 發炎 | D27: =ROUND(V$29,2) -> 0.47 | E27: =ROUND($V$24, 2) -> 0.53 | F27: =ROUND($V$25, 2) -> 1 | G27: =ROUND($V$27, 2) -> 0.69 | J27: =ROUND(V23, 2) -> 0.85 | R27: F1-score | S27: =(2/(1/S25+1/S24)) -> 0.82460137 | T27: =(2/(1/T25+1/T24)) -> 0.91970803 | U27: =(2/(1/U25+1/U24)) -> 0.91596639 | V27: =(2/(1/V25+1/V24)) -> 0.68965517 | W27: =(2/(1/W25+1/W24)) -> 0.95372751 | X27: =(2/(1/X25+1/X24)) -> 0.96907216 | Y27: =(2/(1/Y25+1/Y24)) -> 0.8372615 | Z27: =(2/(1/Z25+1/Z24)) -> 1 | ... AD27: =(2/(1/AD25+1/AD24)) -> 0.80395542
C28: 通道 | D28: =ROUND(W$29,2) -> 0.97 | E28: =ROUND($W$24, 2) -> 0.94 | F28: =ROUND($W$25, 2) -> 0.97 | G28: =ROUND($W$27, 2) -> 0.95 | J28: =ROUND(W23, 2) -> 0.83 | R28: Kappa | S28: =$M$25 -> 0.79611551
C29: 賁門 | D29: =ROUND(X$29,2) -> 0.94 | E29: =ROUND($X$24, 2) -> 0.95 | F29: =ROUND($X$25, 2) -> 0.99 | G29: =ROUND($X$27, 2) -> 0.97 | J29: =ROUND(X23, 2) -> 0.84 | R29: AP | S29: 0.79 | T29: 0.882 | U29: 0.835 | V29: 0.467 | W29: 0.97 | X29: 0.944 | Y29: 0.832 | Z29: 0.995 | AA29: 0.978 | AB29: 0.842 | AC29: 0.803
C30: 異物 | D30: =ROUND(Y$29,2) -> 0.83 | E30: =ROUND($Y$24, 2) -> 0.81 | F30: =ROUND($Y$25, 2) -> 0.86 | G30: =ROUND($Y$27, 2) -> 0.84 | J30: =ROUND(Y23, 2) -> 0.85
C31: 器械 | D31: =ROUND(Z$29,2) -> 1 | E31: =ROUND($Z$24, 2) -> 1 | F31: =ROUND($Z$25, 2) -> 1 | G31: =ROUND($Z$27, 2) -> 1 | J31: =ROUND(Z23, 2) -> 0.84
C32: 人造資訊 | D32: =ROUND(AA$29,2) -> 0.98 | E32: =ROUND($AA$24, 2) -> 0.98 | F32: =ROUND($AA$25, 2) -> 0.96 | G32: =ROUND($AA$27, 2) -> 0.97 | J32: =ROUND(AA23, 2) -> 0.84 | S32: =((T8+U9+V10+W11+X12+Y13+Z14+AA15+AB16+AC17)/(T19+U19+V19+W19+X19+Y19+Z19+AA19+AB19+AC19)) -> 0.85432948
C33: 氣泡 | D33: =ROUND(AB$29,2) -> 0.84 | E33: =ROUND($AB$24, 2) -> 0.84 | F33: =ROUND($AB$25, 2) -> 0.88 | G33: =ROUND($AB$27, 2) -> 0.86 | J33: =ROUND(AB23, 2) -> 0.85
C34: 反光 | D34: =ROUND(AC$29,2) -> 0.8 | E34: =ROUND($AC$24, 2) -> 0.82 | F34: =ROUND($AC$25, 2) -> 0.63 | G34: =ROUND($AC$27, 2) -> 0.71 | J34: =ROUND(AC23, 2) -> 0.86
C35: mean | D35: =ROUND($D$36, 2) -> 0.85 | E35: =ROUND($E$36, 2) -> 0.86 | F35: =ROUND($F$36, 2) -> 0.92 | G35: =ROUND($G$36, 2) -> 0.88 | J35: =ROUND(J36, 2) -> 0.85
D36: =AVERAGE(D24:D34) -> 0.84909091 | E36: =AVERAGE(E24:E34) -> 0.85545455 | F36: =AVERAGE(F24:F34) -> 0.91636364 | G36: =AVERAGE(G24:G34) -> 0.87727273 | J36: =AVERAGE(J24:J34) -> 0.84545455
B39: 結果 | D39: AP | E39: Sensitivity | F39: Precision | G39: F1-score | H39: accuracy | I39: Kappa
B40: RGB-WLI | C40: Dysplasia | D40: =ROUND(S$29,2) -> 0.79 | E40: =ROUND($S$24, 2) -> 0.79 | F40: =ROUND($S$25, 2) -> 0.87 | G40: =ROUND($S$27, 2) -> 0.82 | H40: =ROUND($S$26, 2) -> 0.85 | I40: =ROUND($S$28, 2) -> 0.8
C41: SCC | D41: =ROUND(T$29,2) -> 0.88 | E41: =ROUND($T$24, 2) -> 0.86 | F41: =ROUND($T$25, 2) -> 0.98 | G41: =ROUND($T$27, 2) -> 0.92
C42: 出血 | D42: =ROUND(U$29,2) -> 0.84 | E42: =ROUND($U$24, 2) -> 0.89 | F42: =ROUND($U$25, 2) -> 0.94 | G42: =ROUND($U$27, 2) -> 0.92
C43: 其他 | D43: =ROUND(AVERAGE(V29:AC29),2) -> 0.85 | E43: =ROUND(AD24, 2) -> 0.85 | F43: =ROUND(AD25, 2) -> 0.76 | G43: =ROUND(AD27, 2) -> 0.8
C44: mean | D44: =ROUND($D$36, 2) -> 0.85 | E44: =ROUND($E$36, 2) -> 0.86 | F44: =ROUND($F$36, 2) -> 0.92 | G44: =ROUND($G$36, 2) -> 0.88
D45: =AVERAGE(D40:D43) -> 0.84 | E45: =AVERAGE(E40:E43) -> 0.8475 | F45: =AVERAGE(F40:F43) -> 0.8875 | G45: =AVERAGE(G40:G43) -> 0.865

Sheet HSI
B5: HSI_比例 | R5: HSI_個數
B6: True Predicted | C6: Dysplasia | D6: SCC | E6: 出血 | F6: 發炎 | G6: 通道 | H6: 賁門 | I6: 異物 | J6: 器械 | K6: 人造資訊 | L6: 氣泡 | M6: 反光 | N6: Background | O6: Predicted all | R6: True Predicted | S6: Dysplasia | T6: SCC | U6: 出血 | V6: 發炎 | W6: 通道 | X6: 賁門 | Y6: 異物 | Z6: 器械 | AA6: 人造資訊 | AB6: 氣泡 | AC6: 反光 | AD6: Background | AE6: Predicted all
B7: Dysplasia | C7: 0.89 | E7: 0.01 | N7: 0.11 | O7: =$P7 -> 1.01 | P7: =SUM($C7:$N7) -> 1.01 | R7: Dysplasia | S7: =ROUND(C7*框選統計!$L$8,0) -> 410 | T7: =ROUND(D7*框選統計!$L$9,0) -> 0 | U7: =ROUND(E7*框選統計!$L$10,0) -> 1 | V7: =ROUND(F7*框選統計!$L$11,0) -> 0 | W7: =ROUND(G7*框選統計!$L$12,0) -> 0 | X7: =ROUND(H7*框選統計!$L$13,0) -> 0 | Y7: =ROUND(I7*框選統計!$L$14,0) -> 0 | Z7: =ROUND(J7*框選統計!$L$15,0) -> 0 | AA7: =ROUND(K7*框選統計!$L$16,0) -> 0 | AB7: =ROUND(L7*框選統計!$L$17,0) -> 0 | AC7: =ROUND(M7*框選統計!$L$18,0) -> 0 | AD7: =ROUND(N7*框選統計!$L8,0) -> 51 | AE7: =$AF7 -> 462 | AF7: =SUM($S7:$AD7) -> 462
B8: SCC | D8: 0.92 | N8: 0.01 | O8: =$P8 -> 0.93 | P8: =SUM($C8:$N8) -> 0.93 | R8: SCC | S8: =ROUND(C8*框選統計!$L$8,0) -> 0 | T8: =ROUND(D8*框選統計!$L$9,0) -> 67 | U8: =ROUND(E8*框選統計!$L$10,0) -> 0 | V8: =ROUND(F8*框選統計!$L$11,0) -> 0 | W8: =ROUND(G8*框選統計!$L$12,0) -> 0 | X8: =ROUND(H8*框選統計!$L$13,0) -> 0 | Y8: =ROUND(I8*框選統計!$L$14,0) -> 0 | Z8: =ROUND(J8*框選統計!$L$15,0) -> 0 | AA8: =ROUND(K8*框選統計!$L$16,0) -> 0 | AB8: =ROUND(L8*框選統計!$L$17,0) -> 0 | AC8: =ROUND(M8*框選統計!$L$18,0) -> 0 | AD8: =ROUND(N8*框選統計!$L9,0) -> 1 | AE8: =$AF8 -> 68 | AF8: =SUM($S8:$AD8) -> 68
B9: 出血 | E9: 0.93 | F9: 0.1 | N9: 0.04 | O9: =$P9 -> 1.07 | P9: =SUM($C9:$N9) -> 1.07 | R9: 出血 | S9: =ROUND(C9*框選統計!$L$8,0) -> 0 | T9: =ROUND(D9*框選統計!$L$9,0) -> 0 | U9: =ROUND(E9*框選統計!$L$10,0) -> 113 | V9: =ROUND(F9*框選統計!$L$11,0) -> 2 | W9: =ROUND(G9*框選統計!$L$12,0) -> 0 | X9: =ROUND(H9*框選統計!$L$13,0) -> 0 | Y9: =ROUND(I9*框選統計!$L$14,0) -> 0 | Z9: =ROUND(J9*框選統計!$L$15,0) -> 0 | AA9: =ROUND(K9*框選統計!$L$16,0) -> 0 | AB9: =ROUND(L9*框選統計!$L$17,0) -> 0 | AC9: =ROUND(M9*框選統計!$L$18,0) -> 0 | AD9: =ROUND(N9*框選統計!$L10,0) -> 5 | AE9: =$AF9 -> 120 | AF9: =SUM($S9:$AD9) -> 120
B10: 發炎 | F10: 0.58 | N10: 0.01 | O10: =$P10 -> 0.59 | P10: =SUM($C10:$N10) -> 0.59 | R10: 發炎 | S10: =ROUND(C10*框選統計!$L$8,0) -> 0 | T10: =ROUND(D10*框選統計!$L$9,0) -> 0 | U10: =ROUND(E10*框選統計!$L$10,0) -> 0 | V10: =ROUND(F10*框選統計!$L$11,0) -> 11 | W10: =ROUND(G10*框選統計!$L$12,0) -> 0 | X10: =ROUND(H10*框選統計!$L$13,0) -> 0 | Y10: =ROUND(I10*框選統計!$L$14,0) -> 0 | Z10: =ROUND(J10*框選統計!$L$15,0) -> 0 | AA10: =ROUND(K10*框選統計!$L$16,0) -> 0 | AB10: =ROUND(L10*框選統計!$L$17,0) -> 0 | AC10: =ROUND(M10*框選統計!$L$18,0) -> 0 | AD10: =ROUND(N10*框選統計!$L11,0) -> 0 | AE10: =$AF10 -> 11 | AF10: =SUM($S10:$AD10) -> 11
B11: 通道 | G11: 0.94 | H11: 0.01 | N11: 0.03 | O11: =$P11 -> 0.98 | P11: =SUM($C11:$N11) -> 0.98 | R11: 通道 | S11: =ROUND(C11*框選統計!$L$8,0) -> 0 | T11: =ROUND(D11*框選統計!$L$9,0) -> 0 | U11: =ROUND(E11*框選統計!$L$10,0) -> 0 | V11: =ROUND(F11*框選統計!$L$11,0) -> 0 | W11: =ROUND(G11*框選統計!$L$12,0) -> 371 | X11: =ROUND(H11*框選統計!$L$13,0) -> 1 | Y11: =ROUND(I11*框選統計!$L$14,0) -> 0 | Z11: =ROUND(J11*框選統計!$L$15,0) -> 0 | AA11: =ROUND(K11*框選統計!$L$16,0) -> 0 | AB11: =ROUND(L11*框選統計!$L$17,0) -> 0 | AC11: =ROUND(M11*框選統計!$L$18,0) -> 0 | AD11: =ROUND(N11*框選統計!$L12,0) -> 12 | AE11: =$AF11 -> 384 | AF11: =SUM($S11:$AD11) -> 384
B12: 賁門 | G12: 0.01 | H12: 0.93 | N12: 0.01 | O12: =$P12 -> 0.95 | P12: =SUM($C12:$N12) -> 0.95 | R12: 賁門 | S12: =ROUND(C12*框選統計!$L$8,0) -> 0 | T12: =ROUND(D12*框選統計!$L$9,0) -> 0 | U12: =ROUND(E12*框選統計!$L$10,0) -> 0 | V12: =ROUND(F12*框選統計!$L$11,0) -> 0 | W12: =ROUND(G12*框選統計!$L$12,0) -> 4 | X12: =ROUND(H12*框選統計!$L$13,0) -> 92 | Y12: =ROUND(I12*框選統計!$L$14,0) -> 0 | Z12: =ROUND(J12*框選統計!$L$15,0) -> 0 | AA12: =ROUND(K12*框選統計!$L$16,0) -> 0 | AB12: =ROUND(L12*框選統計!$L$17,0) -> 0 | AC12: =ROUND(M12*框選統計!$L$18,0) -> 0 | AD12: =ROUND(N12*框選統計!$L13,0) -> 1 | AE12: =$AF12 -> 97 | AF12: =SUM($S12:$AD12) -> 97
B13: 異物 | I13: 0.84 | N13: 0.16 | O13: =$P13 -> 1 | P13: =SUM($C13:$N13) -> 1 | R13: 異物 | S13: =ROUND(C13*框選統計!$L$8,0) -> 0 | T13: =ROUND(D13*框選統計!$L$9,0) -> 0 | U13: =ROUND(E13*框選統計!$L$10,0) -> 0 | V13: =ROUND(F13*框選統計!$L$11,0) -> 0 | W13: =ROUND(G13*框選統計!$L$12,0) -> 0 | X13: =ROUND(H13*框選統計!$L$13,0) -> 0 | Y13: =ROUND(I13*框選統計!$L$14,0) -> 385 | Z13: =ROUND(J13*框選統計!$L$15,0) -> 0 | AA13: =ROUND(K13*框選統計!$L$16,0) -> 0 | AB13: =ROUND(L13*框選統計!$L$17,0) -> 0 | AC13: =ROUND(M13*框選統計!$L$18,0) -> 0 | AD13: =ROUND(N13*框選統計!$L14,0) -> 73 | AE13: =$AF13 -> 458 | AF13: =SUM($S13:$AD13) -> 458
B14: 器械 | J14: 1 | N14: 0 | O14: =$P14 -> 1 | P14: =SUM($C14:$N14) -> 1 | R14: 器械 | S14: =ROUND(C14*框選統計!$L$8,0) -> 0 | T14: =ROUND(D14*框選統計!$L$9,0) -> 0 | U14: =ROUND(E14*框選統計!$L$10,0) -> 0 | V14: =ROUND(F14*框選統計!$L$11,0) -> 0 | W14: =ROUND(G14*框選統計!$L$12,0) -> 0 | X14: =ROUND(H14*框選統計!$L$13,0) -> 0 | Y14: =ROUND(I14*框選統計!$L$14,0) -> 0 | Z14: =ROUND(J14*框選統計!$L$15,0) -> 16 | AA14: =ROUND(K14*框選統計!$L$16,0) -> 0 | AB14: =ROUND(L14*框選統計!$L$17,0) -> 0 | AC14: =ROUND(M14*框選統計!$L$18,0) -> 0 | AD14: =ROUND(N14*框選統計!$L15,0) -> 0 | AE14: =$AF14 -> 16 | AF14: =SUM($S14:$AD14) -> 16
B15: 人造資訊 | K15: 0.97 | N15: 0.06 | O15: =$P15 -> 1.03 | P15: =SUM($C15:$N15) -> 1.03 | R15: 人造資訊 | S15: =ROUND(C15*框選統計!$L$8,0) -> 0 | T15: =ROUND(D15*框選統計!$L$9,0) -> 0 | U15: =ROUND(E15*框選統計!$L$10,0) -> 0 | V15: =ROUND(F15*框選統計!$L$11,0) -> 0 | W15: =ROUND(G15*框選統計!$L$12,0) -> 0 | X15: =ROUND(H15*框選統計!$L$13,0) -> 0 | Y15: =ROUND(I15*框選統計!$L$14,0) -> 0 | Z15: =ROUND(J15*框選統計!$L$15,0) -> 0 | AA15: =ROUND(K15*框選統計!$L$16,0) -> 209 | AB15: =ROUND(L15*框選統計!$L$17,0) -> 0 | AC15: =ROUND(M15*框選統計!$L$18,0) -> 0 | AD15: =ROUND(N15*框選統計!$L16,0) -> 13 | AE15: =$AF15 -> 222 | AF15: =SUM($S15:$AD15) -> 222
B16: 氣泡 | L16: 0.86 | N16: 0.1 | O16: =$P16 -> 0.96 | P16: =SUM($C16:$N16) -> 0.96 | R16: 氣泡 | S16: =ROUND(C16*框選統計!$L$8,0) -> 0 | T16: =ROUND(D16*框選統計!$L$9,0) -> 0 | U16: =ROUND(E16*框選統計!$L$10,0) -> 0 | V16: =ROUND(F16*框選統計!$L$11,0) -> 0 | W16: =ROUND(G16*框選統計!$L$12,0) -> 0 | X16: =ROUND(H16*框選統計!$L$13,0) -> 0 | Y16: =ROUND(I16*框選統計!$L$14,0) -> 0 | Z16: =ROUND(J16*框選統計!$L$15,0) -> 0 | AA16: =ROUND(K16*框選統計!$L$16,0) -> 0 | AB16: =ROUND(L16*框選統計!$L$17,0) -> 367 | AC16: =ROUND(M16*框選統計!$L$18,0) -> 0 | AD16: =ROUND(N16*框選統計!$L17,0) -> 43 | AE16: =$AF16 -> 410 | AF16: =SUM($S16:$AD16) -> 410
B17: 反光 | L17: 0.02 | M17: 0.86 | N17: 0.48 | O17: =$P17 -> 1.36 | P17: =SUM($C17:$N17) -> 1.36 | R17: 反光 | S17: =ROUND(C17*框選統計!$L$8,0) -> 0 | T17: =ROUND(D17*框選統計!$L$9,0) -> 0 | U17: =ROUND(E17*框選統計!$L$10,0) -> 0 | V17: =ROUND(F17*框選統計!$L$11,0) -> 0 | W17: =ROUND(G17*框選統計!$L$12,0) -> 0 | X17: =ROUND(H17*框選統計!$L$13,0) -> 0 | Y17: =ROUND(I17*框選統計!$L$14,0) -> 0 | Z17: =ROUND(J17*框選統計!$L$15,0) -> 0 | AA17: =ROUND(K17*框選統計!$L$16,0) -> 0 | AB17: =ROUND(L17*框選統計!$L$17,0) -> 9 | AC17: =ROUND(M17*框選統計!$L$18,0) -> 1182 | AD17: =ROUND(N17*框選統計!$L18,0) -> 660 | AE17: =$AF17 -> 1851 | AF17: =SUM($S17:$AD17) -> 1851
B18: Background | C18: 0.11 | D18: 0.08 | E18: 0.06 | F18: 0.32 | G18: 0.05 | H18: 0.06 | I18: 0.16 | J18: 0 | K18: 0.03 | L18: 0.12 | M18: 0.14 | N18: 0 | O18: =$P18 -> 1.13 | P18: =SUM($C18:$N18) -> 1.13 | R18: Background | S18: =ROUND(C18*框選統計!$L$8,0) -> 51 | T18: =ROUND(D18*框選統計!$L$9,0) -> 6 | U18: =ROUND(E18*框選統計!$L$10,0) -> 7 | V18: =ROUND(F18*框選統計!$L$11,0) -> 6 | W18: =ROUND(G18*框選統計!$L$12,0) -> 20 | X18: =ROUND(H18*框選統計!$L$13,0) -> 6 | Y18: =ROUND(I18*框選統計!$L$14,0) -> 73 | Z18: =ROUND(J18*框選統計!$L$15,0) -> 0 | AA18: =ROUND(K18*框選統計!$L$16,0) -> 6 | AB18: =ROUND(L18*框選統計!$L$17,0) -> 51 | AC18: =ROUND(M18*框選統計!$L$18,0) -> 192 | AD18: =ROUND(N18*框選統計!$L19,0) -> 0 | AE18: =$AF18 -> 418 | AF18: =SUM($S18:$AD18) -> 418
B19: True all | C19: =C$20 -> 1 | D19: =D$20 -> 1 | E19: =E$20 -> 1 | F19: =F$20 -> 1 | G19: =G$20 -> 1 | H19: =H$20 -> 1 | I19: =I$20 -> 1 | J19: =J$20 -> 1 | ... N19: =N$20 -> 1.01 | P19: =SUM(P7:P18) -> 12.01 | R19: True all | S19: =S$20 -> 461 | T19: =T$20 -> 73 | U19: =U$20 -> 121 | V19: =V$20 -> 19 | W19: =W$20 -> 395 | X19: =X$20 -> 99 | Y19: =Y$20 -> 458 | Z19: =Z$20 -> 16 | ... AD19: =AD$20 -> 859 | AE19: =IF(AE20=AF19,AE20,"no") -> 4517 | AF19: =SUM(AF7:AF18) -> 4517
C20: =SUM(C$7:C$18) -> 1 | D20: =SUM(D$7:D$18) -> 1 | E20: =SUM(E$7:E$18) -> 1 | F20: =SUM(F$7:F$18) -> 1 | G20: =SUM(G$7:G$18) -> 1 | H20: =SUM(H$7:H$18) -> 1 | I20: =SUM(I$7:I$18) -> 1 | J20: =SUM(J$7:J$18) -> 1 | ... N20: =SUM(N$7:N$18) -> 1.01 | O20: =SUM(C20:N20) -> 12.01 | S20: =SUM(S$7:S$18) -> 461 | T20: =SUM(T$7:T$18) -> 73 | U20: =SUM(U$7:U$18) -> 121 | V20: =SUM(V$7:V$18) -> 19 | W20: =SUM(W$7:W$18) -> 395 | X20: =SUM(X$7:X$18) -> 99 | Y20: =SUM(Y$7:Y$18) -> 458 | Z20: =SUM(Z$7:Z$18) -> 16 | ... AD20: =SUM(AD$7:AD$18) -> 859 | AE20: =SUM(S20:AD20) -> 4517
AE21: =SUM(S20:AC20) -> 3658
AD22: others
B23: 結果 | D23: AP | E23: Sensitivity | F23: Precision | G23: F1-score | H23: accuracy | I23: Kappa | J23: Specificity | R23: Specificity | S23: =((T8+U9+V10+W11+X12+Y13+Z14+AA15+AB16+AC17)/(T19+U19+V19+W19+X19+Y19+Z19+AA19+AB19+AC19)) -> 0.87988739 | T23: =((S7+U9+V10+W11+X12+Y13+Z14+AA15+AB16+AC17)/(S19+U19+V19+W19+X19+Y19+Z19+AA19+AB19+AC19)) -> 0.88033473 | U23: =((T8+S7+V10+W11+X12+Y13+Z14+AA15+AB16+AC17)/(T19+S19+V19+W19+X19+Y19+Z19+AA19+AB19+AC19)) -> 0.87927622 | V23: =((T8+U9+S7+W11+X12+Y13+Z14+AA15+AB16+AC17)/(T19+U19+S19+W19+X19+Y19+Z19+AA19+AB19+AC19)) -> 0.88266007 | W23: =((T8+U9+V10+S7+X12+Y13+Z14+AA15+AB16+AC17)/(T19+U19+V19+S19+X19+Y19+Z19+AA19+AB19+AC19)) -> 0.87404229 | X23: =((T8+U9+V10+W11+S7+Y13+Z14+AA15+AB16+AC17)/(T19+U19+V19+W19+S19+Y19+Z19+AA19+AB19+AC19)) -> 0.8797415 | Y23: =((T8+U9+V10+W11+X12+S7+Z14+AA15+AB16+AC17)/(T19+U19+V19+W19+X19+S19+Z19+AA19+AB19+AC19)) -> 0.886875 | Z23: =((T8+U9+V10+W11+X12+Y13+S7+AA15+AB16+AC17)/(T19+U19+V19+W19+X19+Y19+S19+AA19+AB19+AC19)) -> 0.88056013 | AA23: =((T8+U9+V10+W11+X12+Y13+Z14+S7+AB16+AC17)/(T19+U19+V19+W19+X19+Y19+Z19+S19+AB19+AC19)) -> 0.87539936 | AB23: =((T8+U9+V10+W11+X12+Y13+Z14+AA15+S7+AC17)/(T19+U19+V19+W19+X19+Y19+Z19+AA19+S19+AC19)) -> 0.88393686 | AC23: =((T8+U9+V10+W11+X12+Y13+Z14+AA15+AB16+S7)/(T19+U19+V19+W19+X19+Y19+Z19+AA19+AB19+S19)) -> 0.89360771
B24: HSI-NBI | C24: Dysplasia | D24: =ROUND(S$29,2) -> 0.86 | E24: =ROUND($S$24, 2) -> 0.89 | F24: =ROUND($S$25, 2) -> 0.89 | G24: =ROUND($S$27, 2) -> 0.89 | H24: =ROUND($S$26, 2) -> 0.88 | I24: =ROUND($S$28, 2) -> 0.84 | J24: =ROUND(S23, 2) -> 0.88 | M24: kappa | N24: pe | O24: po | R24: Sensitivity | S24: =(S7/S$19) -> 0.88937093 | T24: =(T8/T$19) -> 0.91780822 | U24: =(U9/U$19) -> 0.9338843 | V24: =(V10/V$19) -> 0.57894737 | W24: =(W11/W$19) -> 0.93924051 | X24: =(X12/X$19) -> 0.92929293 | Y24: =(Y13/Y$19) -> 0.84061135 | Z24: =(Z14/Z$19) -> 1 | AA24: =(AA15/AA$19) -> 0.97209302 | AB24: =(AB16/AB$19) -> 0.85948478 | AC24: =(AC17/AC$19) -> 0.86026201 | AD24: =((V10+W11+X12+Y13+Z14+AA15+AB16+AC17)/(V19+W19+X19+Y19+Z19+AA19+AB19+AC19)) -> 0.87678988
C25: SCC | D25: =ROUND(T$29,2) -> 0.9 | E25: =ROUND($T$24, 2) -> 0.92 | F25: =ROUND($T$25, 2) -> 0.99 | G25: =ROUND($T$27, 2) -> 0.95 | J25: =ROUND(T23, 2) -> 0.88 | M25: =(($O$25-$N$25)/(1-$N$25)) -> 0.84075788 | N25: =(($S$19*$AE$7+$T$19*$AE$8+$U$19*$AE$9+$V$19*$AE$10+$W$19*$AE$11+$X$19*$AE$12+$Y$19*$AE$13+$Z$19*$AE$14+$AA$19*$AE$15+$AB$19*$AE$16+$AC$19*$AE$17)/(框選統計!L19*框選統計!L19)) -> 0.25171656 | O25: =(($S$7+$T$8+$U$9+$V$10+$W$11+$X$12+$Y$13+$Z$14+$AA$15+$AB$16+$AC$17)/(框選統計!L19)) -> 0.88084176 | R25: Precision | S25: =(S7/$AE7) -> 0.88744589 | T25: =(T8/$AE8) -> 0.98529412 | U25: =(U9/$AE9) -> 0.94166667 | V25: =(V10/$AE10) -> 1 | W25: =(W11/$AE11) -> 0.96614583 | X25: =(X12/$AE12) -> 0.94845361 | Y25: =(Y13/$AE13) -> 0.84061135 | Z25: =(Z14/$AE14) -> 1 | AA25: =(AA15/$AE15) -> 0.94144144 | AB25: =(AB16/$AE16) -> 0.89512195 | AC25: =(AC17/$AE17) -> 0.63857374 | AD25: =((V10+W11+X12+Y13+Z14+AA15+AB16+AC17)/(AE10+AE11+AE12+AE13+AE14+AE15+AE16+AE17)) -> 0.76340968
C26: 出血 | D26: =ROUND(U$29,2) -> 0.93 | E26: =ROUND($U$24, 2) -> 0.93 | F26: =ROUND($U$25, 2) -> 0.94 | G26: =ROUND($U$27, 2) -> 0.94 | J26: =ROUND(U23, 2) -> 0.88 | R26: Accuracy | S26: =((S7+T8+U9+V10+W11+X12+Y13+Z14+AA15+AB16+AC17)/(框選統計!L19)) -> 0.88084176
C27: 發炎 | D27: =ROUND(V$29,2) -> 0.48 | E27: =ROUND($V$24, 2) -> 0.58 | F27: =ROUND($V$25, 2) -> 1 | G27: =ROUND($V$27, 2) -> 0.73 | J27: =ROUND(V23, 2) -> 0.88 | R27: F1-score | S27: =(2/(1/S25+1/S24)) -> 0.88840737 | T27: =(2/(1/T25+1/T24)) -> 0.95035461 | U27: =(2/(1/U25+1/U24)) -> 0.93775934 | V27: =(2/(1/V25+1/V24)) -> 0.73333333 | W27: =(2/(1/W25+1/W24)) -> 0.95250321 | X27: =(2/(1/X25+1/X24)) -> 0.93877551 | Y27: =(2/(1/Y25+1/Y24)) -> 0.84061135 | Z27: =(2/(1/Z25+1/Z24)) -> 1 | ... AD27: =(2/(1/AD25+1/AD24)) -> 0.81618103
C28: 通道 | D28: =ROUND(W$29,2) -> 0.95 | E28: =ROUND($W$24, 2) -> 0.94 | F28: =ROUND($W$25, 2) -> 0.97 | G28: =ROUND($W$27, 2) -> 0.95 | J28: =ROUND(W23, 2) -> 0.87 | R28: Kappa | S28: =$M$25 -> 0.84075788
C29: 賁門 | D29: =ROUND(X$29,2) -> 0.96 | E29: =ROUND($X$24, 2) -> 0.93 | F29: =ROUND($X$25, 2) -> 0.95 | G29: =ROUND($X$27, 2) -> 0.94 | J29: =ROUND(X23, 2) -> 0.88 | R29: AP | S29: 0.858 | T29: 0.901 | U29: 0.93 | V29: 0.483 | W29: 0.946 | X29: 0.962 | Y29: 0.816 | Z29: 0.995 | AA29: 0.971 | AB29: 0.855 | AC29: 0.838
C30: 異物 | D30: =ROUND(Y$29,2) -> 0.82 | E30: =ROUND($Y$24, 2) -> 0.84 | F30: =ROUND($Y$25, 2) -> 0.84 | G30: =ROUND($Y$27, 2) -> 0.84 | J30: =ROUND(Y23, 2) -> 0.89
C31: 器械 | D31: =ROUND(Z$29,2) -> 1 | E31: =ROUND($Z$24, 2) -> 1 | F31: =ROUND($Z$25, 2) -> 1 | G31: =ROUND($Z$27, 2) -> 1 | J31: =ROUND(Z23, 2) -> 0.88
C32: 人造資訊 | D32: =ROUND(AA$29,2) -> 0.97 | E32: =ROUND($AA$24, 2) -> 0.97 | F32: =ROUND($AA$25, 2) -> 0.94 | G32: =ROUND($AA$27, 2) -> 0.96 | J32: =ROUND(AA23, 2) -> 0.88
C33: 氣泡 | D33: =ROUND(AB$29,2) -> 0.86 | E33: =ROUND($AB$24, 2) -> 0.86 | F33: =ROUND($AB$25, 2) -> 0.9 | G33: =ROUND($AB$27, 2) -> 0.88 | J33: =ROUND(AB23, 2) -> 0.88
C34: 反光 | D34: =ROUND(AC$29,2) -> 0.84 | E34: =ROUND($AC$24, 2) -> 0.86 | F34: =ROUND($AC$25, 2) -> 0.64 | G34: =ROUND($AC$27, 2) -> 0.73 | J34: =ROUND(AC23, 2) -> 0.89
C35: mean | D35: =ROUND($D$36, 2) -> 0.87 | E35: =ROUND($E$36, 2) -> 0.88 | F35: =ROUND($F$36, 2) -> 0.91 | G35: =ROUND($G$36, 2) -> 0.89 | J35: =ROUND(J36, 2) -> 0.88
D36: =AVERAGE(D24:D34) -> 0.87 | E36: =AVERAGE(E24:E34) -> 0.88363636 | F36: =AVERAGE(F24:F34) -> 0.91454545 | G36: =AVERAGE(G24:G34) -> 0.89181818 | J36: =AVERAGE(J24:J34) -> 0.88090909
B39: 結果 | D39: AP | E39: Sensitivity | F39: Precision | G39: F1-score | H39: accuracy | I39: Kappa
B40: HSI-NBI | C40: Dysplasia | D40: =ROUND(S$29,2) -> 0.86 | E40: =ROUND($S$24, 2) -> 0.89 | F40: =ROUND($S$25, 2) -> 0.89 | G40: =ROUND($S$27, 2) -> 0.89 | H40: =ROUND($S$26, 2) -> 0.88 | I40: =ROUND($S$28, 2) -> 0.84
C41: SCC | D41: =ROUND(T$29,2) -> 0.9 | E41: =ROUND($T$24, 2) -> 0.92 | F41: =ROUND($T$25, 2) -> 0.99 | G41: =ROUND($T$27, 2) -> 0.95
C42: 出血 | D42: =ROUND(U$29,2) -> 0.93 | E42: =ROUND($U$24, 2) -> 0.93 | F42: =ROUND($U$25, 2) -> 0.94 | G42: =ROUND($U$27, 2) -> 0.94
C43: 其他 | D43: =ROUND(AVERAGE(V29:AC29),2) -> 0.86 | E43: =ROUND(AD24, 2) -> 0.88 | F43: =ROUND(AD25, 2) -> 0.76 | G43: =ROUND(AD27, 2) -> 0.82
C44: mean | D44: =ROUND($D$36, 2) -> 0.87 | E44: =ROUND($E$36, 2) -> 0.88 | F44: =ROUND($F$36, 2) -> 0.91 | G44: =ROUND($G$36, 2) -> 0.89
D45: =AVERAGE(D40:D43) -> 0.8875 | E45: =AVERAGE(E40:E43) -> 0.905 | F45: =AVERAGE(F40:F43) -> 0.895 | G45: =AVERAGE(G40:G43) -> 0.9

Sheet 結果
C4: 結果 | E4: AP | F4: Sensitivity | G4: Precision | H4: F1-score | I4: accuracy | J4: Kappa | L4: 結果 | N4: AP | O4: Sensitivity | P4: Precision | Q4: F1-score | R4: accuracy | S4: Kappa
C5: RGB-WLI | D5: Dysplasia | E5: 0.79 | F5: 0.79 | G5: 0.87 | H5: 0.82 | I5: 0.85 | J5: 0.8 | L5: HSI-NBI | M5: Dysplasia | N5: 0.86 | O5: 0.89 | P5: 0.89 | Q5: 0.89 | R5: 0.88 | S5: 0.84
D6: SCC | E6: 0.88 | F6: 0.86 | G6: 0.98 | H6: 0.92 | M6: SCC | N6: 0.9 | O6: 0.92 | P6: 0.99 | Q6: 0.95
D7: 出血 | E7: 0.84 | F7: 0.89 | G7: 0.94 | H7: 0.92 | M7: 出血 | N7: 0.93 | O7: 0.93 | P7: 0.94 | Q7: 0.94
D8: 發炎 | E8: 0.47 | F8: 0.53 | G8: 1 | H8: 0.69 | M8: 發炎 | N8: 0.48 | O8: 0.58 | P8: 1 | Q8: 0.73
D9: 通道 | E9: 0.97 | F9: 0.94 | G9: 0.97 | H9: 0.95 | M9: 通道 | N9: 0.95 | O9: 0.94 | P9: 0.97 | Q9: 0.95
D10: 賁門 | E10: 0.94 | F10: 0.95 | G10: 0.99 | H10: 0.97 | M10: 賁門 | N10: 0.96 | O10: 0.93 | P10: 0.95 | Q10: 0.94
D11: 異物 | E11: 0.83 | F11: 0.81 | G11: 0.86 | H11: 0.84 | M11: 異物 | N11: 0.82 | O11: 0.84 | P11: 0.84 | Q11: 0.84
D12: 器械 | E12: 1 | F12: 1 | G12: 1 | H12: 1 | M12: 器械 | N12: 1 | O12: 1 | P12: 1 | Q12: 1
D13: 人造資訊 | E13: 0.98 | F13: 0.98 | G13: 0.96 | H13: 0.97 | M13: 人造資訊 | N13: 0.97 | O13: 0.97 | P13: 0.94 | Q13: 0.96
D14: 氣泡 | E14: 0.84 | F14: 0.84 | G14: 0.88 | H14: 0.86 | M14: 氣泡 | N14: 0.86 | O14: 0.86 | P14: 0.9 | Q14: 0.88
D15: 反光 | E15: 0.8 | F15: 0.82 | G15: 0.63 | H15: 0.71 | M15: 反光 | N15: 0.84 | O15: 0.86 | P15: 0.64 | Q15: 0.73
D16: mean | E16: 0.85 | F16: 0.86 | G16: 0.92 | H16: 0.88 | M16: mean | N16: 0.87 | O16: 0.88 | P16: 0.91 | Q16: 0.89
