Workbook

Sheet 圖總表
A1: 次序 | B1: Filename | C1: 病歷號 | D1: 程度 | F1: A | G1: B | H1: C息肉 | I1: D出血 | J1: E發炎 | K1: I通道 | L1: J噴門 | M1: K異物 | N1: S器械 | O1: T文字 | P1: U氣泡 | Q1: V反光
A2: =ROW()-1 -> 1 | B2: 180518-0938-21.jpg | C2: 26001648 | D2: dysplasia | K2: 1 | P2: 3
A3: =ROW()-1 -> 2 | B3: 180518-0938-28.jpg | C3: 26001648 | D3: dysplasia | K3: 1
A4: =ROW()-1 -> 3 | B4: 180518-0938-39.jpg | C4: 26001648 | D4: dysplasia | K4: 1 | P4: 1 | Q4: 1
A5: =ROW()-1 -> 4 | B5: 180518-0938-47.jpg | C5: 26001648 | D5: dysplasia | K5: 1 | P5: 1 | Q5: 1
A6: =ROW()-1 -> 5 | B6: 180518-0938-52.jpg | C6: 26001648 | D6: dysplasia | K6: 1 | P6: 1 | Q6: 1
A7: =ROW()-1 -> 6 | B7: 180518-0939-00.jpg | C7: 26001648 | D7: dysplasia | P7: 1 | Q7: 17
A8: =ROW()-1 -> 7 | B8: 180518-0939-25.jpg | C8: 26001648 | D8: dysplasia | P8: 2 | Q8: 6
A9: =ROW()-1 -> 8 | B9: 190313-1101-43.jpg | C9: 26077278 | D9: dysplasia | P9: 3
A10: =ROW()-1 -> 9 | B10: 190313-1101-52.jpg | C10: 26077278 | D10: dysplasia | K10: 1 | P10: 3 | Q10: 2
A11: =ROW()-1 -> 10 | B11: 190313-1101-59.jpg | C11: 26077278 | D11: dysplasia | P11: 2
A12: =ROW()-1 -> 11 | B12: 190313-1102-03.jpg | C12: 26077278 | D12: dysplasia | K12: 1 | M12: 3 | P12: 1
A13: =ROW()-1 -> 12 | B13: 190313-1102-08.jpg | C13: 26077278 | D13: dysplasia | J13: 1 | K13: 1 | M13: 1 | P13: 4 | Q13: 1
A14: =ROW()-1 -> 13 | B14: 190313-1103-37.jpg | C14: 26077278 | D14: dysplasia | H14: 1 | K14: 1 | M14: 1 | P14: 2
A15: =ROW()-1 -> 14 | B15: 190313-1103-40.jpg | C15: 26077278 | D15: dysplasia | F15: 1 | H15: 1 | M15: 1 | P15: 1
A16: =ROW()-1 -> 15 | B16: 08888710 (2).jpg | C16: 8888710 | D16: normal | K16: 1 | P16: 2
A17: =ROW()-1 -> 16 | B17: 09132978_20141226_WL.jpg | C17: 9132978 | D17: dysplasia | K17: 1 | M17: 1 | P17: 8
A18: =ROW()-1 -> 17 | B18: 11218613 (2).jpg | C18: 11218613 | D18: normal | K18: 1 | Q18: 1
A19: =ROW()-1 -> 18 | B19: 14608492 (2).jpg | C19: 14608492 | D19: normal | K19: 1 | P19: 1
A20: =ROW()-1 -> 19 | B20: 17491749_20190422_ES_0_7_7.jpg | C20: 17491749 | D20: SCC | F20: 1 | G20: 1 | I20: 3 | K20: 1 | P20: 2 | Q20: 3
A21: =ROW()-1 -> 20 | B21: 17491749_20190422_ES_0_10_10.jpg | C21: 17491749 | D21: SCC | F21: 4 | G21: 1 | K21: 1 | Q21: 2
A22: =ROW()-1 -> 21 | B22: 17491749_20190422_ES_0_46_46.jpg | C22: 17491749 | D22: SCC | F22: 1 | G22: 2 | K22: 1 | Q22: 7
A23: =ROW()-1 -> 22 | B23: 18758056_20160115_WL SCC.jpg | C23: 18758056 | D23: SCC | K23: 1 | M23: 2
A24: =ROW()-1 -> 23 | B24: 18838646_20150508_WL.jpg | C24: 18838646 | D24: dysplasia | G24: 1 | K24: 1 | O24: 5
A25: =ROW()-1 -> 24 | B25: 19681681_20150626_WL.jpg | C25: 19681681 | D25: dysplasia | K25: 1
A26: =ROW()-1 -> 25 | B26: 19757962_20150312_SCC WL.jpg | C26: 19757962 | D26: SCC | I26: 5 | K26: 1
A27: =ROW()-1 -> 26 | B27: 21221648_20141030_WL.jpg | C27: 21221648 | D27: SCC | F27: 2 | G27: 2 | K27: 1
A28: =ROW()-1 -> 27 | B28: 21313923_20151118_WL.jpg | C28: 21313923 | D28: dysplasia | F28: 1 | K28: 1 | P28: 4
A29: =ROW()-1 -> 28 | B29: 21591967_20180927_ES_0_9_9.jpg | C29: 21591967 | D29: dysplasia | E29: JESB2 and B3, IPCL Vn SCC in situ | F29: 4 | G29: 1 | I29: 1 | K29: 1 | O29: 8
A30: =ROW()-1 -> 29 | B30: 21591967_20180927_ES_0_20_20.jpg | C30: 21591967 | D30: dysplasia | F30: 1 | K30: 1 | M30: 1 | O30: 8 | P30: 2
A31: =ROW()-1 -> 30 | B31: 21591967_20180927_ES_0_21_21.jpg | C31: 21591967 | D31: dysplasia | F31: 6 | O31: 8 | Q31: 3
A32: =ROW()-1 -> 31 | B32: 21591967_20180927_ES_0_30_30.jpg | C32: 21591967 | D32: dysplasia | G32: 2 | I32: 1 | K32: 1 | M32: 1 | O32: 8 | P32: 2
A33: =ROW()-1 -> 32 | B33: 21591967_20180927_ES_0_31_31.jpg | C33: 21591967 | D33: dysplasia | F33: 3 | G33: 1 | I33: 1 | K33: 1 | M33: 1 | O33: 8 | P33: 2 | Q33: 1
A34: =ROW()-1 -> 33 | B34: 21832900_20150918_WL.jpg | C34: 21832900 | D34: dysplasia | K34: 1 | O34: 9
A35: =ROW()-1 -> 34 | B35: 22141522_20150320_SCC WL.jpg | C35: 22141522 | D35: SCC | G35: 2 | I35: 1 | K35: 1 | M35: 1 | Q35: 1
A36: =ROW()-1 -> 35 | B36: 22523449_20131202_WL.jpg | C36: 22523449 | D36: dysplasia | K36: 1
A37: =ROW()-1 -> 36 | B37: 22948922_20141016_WL SCC.jpg | C37: 22948922 | D37: SCC | F37: 1 | G37: 2 | K37: 1 | M37: 3
A38: =ROW()-1 -> 37 | B38: 22979000_20150320_SCC WL.jpg | C38: 22979000 | D38: SCC | F38: 1 | K38: 1 | M38: 1 | P38: 1 | Q38: 1
A39: =ROW()-1 -> 38 | B39: 23516901_20131203_WL.jpg | C39: 23516901 | D39: dysplasia | F39: 2 | K39: 1
A40: =ROW()-1 -> 39 | B40: 24314682_20181012_ES_0_6_6.jpg | C40: 24314682 | D40: dysplasia | K40: 1 | P40: 1
...

Sheet 病歷表
A1: 病歷號 | B1: 數量 | C1: 分級 | E1: 病例個數 | F1: =COUNTA(A:A)-1 -> 143
A2: {=IFERROR(INDEX(圖總表!$C$2:$C$2068, MATCH(0, COUNTIF($A$1:A1, 圖總表!$C$2:$C$2068), 0)), "")} -> 26001648 | B2: =COUNTIF(圖總表!$C$2:$C$2068,A2) -> 8 | C2: =VLOOKUP(A2,圖總表!C:D,2,0) -> dysplasia | E2: 圖總數 | F2: =SUM(B:B) -> 2067
A3: {=IFERROR(INDEX(圖總表!$C$2:$C$2068, MATCH(0, COUNTIF($A$1:A2, 圖總表!$C$2:$C$2068), 0)), "")} -> 26077278 | B3: =COUNTIF(圖總表!$C$2:$C$2068,A3) -> 7 | C3: =VLOOKUP(A3,圖總表!C:D,2,0) -> dysplasia
A4: {=IFERROR(INDEX(圖總表!$C$2:$C$2068, MATCH(0, COUNTIF($A$1:A3, 圖總表!$C$2:$C$2068), 0)), "")} -> 8888710 | B4: =COUNTIF(圖總表!$C$2:$C$2068,A4) -> 1 | C4: =VLOOKUP(A4,圖總表!C:D,2,0) -> normal
A5: {=IFERROR(INDEX(圖總表!$C$2:$C$2068, MATCH(0, COUNTIF($A$1:A4, 圖總表!$C$2:$C$2068), 0)), "")} -> 9132978 | B5: =COUNTIF(圖總表!$C$2:$C$2068,A5) -> 1 | C5: =VLOOKUP(A5,圖總表!C:D,2,0) -> dysplasia
A6: {=IFERROR(INDEX(圖總表!$C$2:$C$2068, MATCH(0, COUNTIF($A$1:A5, 圖總表!$C$2:$C$2068), 0)), "")} -> 11218613 | B6: =COUNTIF(圖總表!$C$2:$C$2068,A6) -> 1 | C6: =VLOOKUP(A6,圖總表!C:D,2,0) -> normal
A7: {=IFERROR(INDEX(圖總表!$C$2:$C$2068, MATCH(0, COUNTIF($A$1:A6, 圖總表!$C$2:$C$2068), 0)), "")} -> 14608492 | B7: =COUNTIF(圖總表!$C$2:$C$2068,A7) -> 1 | C7: =VLOOKUP(A7,圖總表!C:D,2,0) -> normal
A8: {=IFERROR(INDEX(圖總表!$C$2:$C$2068, MATCH(0, COUNTIF($A$1:A7, 圖總表!$C$2:$C$2068), 0)), "")} -> 17491749 | B8: =COUNTIF(圖總表!$C$2:$C$2068,A8) -> 3 | C8: =VLOOKUP(A8,圖總表!C:D,2,0) -> SCC
A9: {=IFERROR(INDEX(圖總表!$C$2:$C$2068, MATCH(0, COUNTIF($A$1:A8, 圖總表!$C$2:$C$2068), 0)), "")} -> 18758056 | B9: =COUNTIF(圖總表!$C$2:$C$2068,A9) -> 1 | C9: =VLOOKUP(A9,圖總表!C:D,2,0) -> SCC
A10: {=IFERROR(INDEX(圖總表!$C$2:$C$2068, MATCH(0, COUNTIF($A$1:A9, 圖總表!$C$2:$C$2068), 0)), "")} -> 18838646 | B10: =COUNTIF(圖總表!$C$2:$C$2068,A10) -> 1 | C10: =VLOOKUP(A10,圖總表!C:D,2,0) -> dysplasia
A11: {=IFERROR(INDEX(圖總表!$C$2:$C$2068, MATCH(0, COUNTIF($A$1:A10, 圖總表!$C$2:$C$2068), 0)), "")} -> 19681681 | B11: =COUNTIF(圖總表!$C$2:$C$2068,A11) -> 1 | C11: =VLOOKUP(A11,圖總表!C:D,2,0) -> dysplasia
A12: {=IFERROR(INDEX(圖總表!$C$2:$C$2068, MATCH(0, COUNTIF($A$1:A11, 圖總表!$C$2:$C$2068), 0)), "")} -> 19757962 | B12: =COUNTIF(圖總表!$C$2:$C$2068,A12) -> 1 | C12: =VLOOKUP(A12,圖總表!C:D,2,0) -> SCC
A13: {=IFERROR(INDEX(圖總表!$C$2:$C$2068, MATCH(0, COUNTIF($A$1:A12, 圖總表!$C$2:$C$2068), 0)), "")} -> 21221648 | B13: =COUNTIF(圖總表!$C$2:$C$2068,A13) -> 1 | C13: =VLOOKUP(A13,圖總表!C:D,2,0) -> SCC
A14: {=IFERROR(INDEX(圖總表!$C$2:$C$2068, MATCH(0, COUNTIF($A$1:A13, 圖總表!$C$2:$C$2068), 0)), "")} -> 21313923 | B14: =COUNTIF(圖總表!$C$2:$C$2068,A14) -> 1 | C14: =VLOOKUP(A14,圖總表!C:D,2,0) -> dysplasia
... A144: {=IFERROR(INDEX(圖總表!$C$2:$C$2068, MATCH(0, COUNTIF($A$1:A143, 圖總表!$C$2:$C$2068), 0)), "")} -> 24505911 | B144: =COUNTIF(圖總表!$C$2:$C$2068,A144) -> 7 | C144: =VLOOKUP(A144,圖總表!C:D,2,0) -> Dysplasia

Sheet 分級表
A1: 分級統計 | B1: 病例數 | C1: 圖片數量 | D1: 備註
A2: {=IFERROR(INDEX(病歷表!$C$2:$C$3416, MATCH(0, COUNTIF($A$1:A1, 病歷表!$C$2:$C$3416), 0)), "")} -> dysplasia | B2: =COUNTIF(病歷表!C:C,A2) -> 47 | C2: =SUMIF(病歷表!$C$2:$C$200,A2,病歷表!$B$2:$B$200) -> 441
A3: {=IFERROR(INDEX(病歷表!$C$2:$C$3416, MATCH(0, COUNTIF($A$1:A2, 病歷表!$C$2:$C$3416), 0)), "")} -> normal | B3: =COUNTIF(病歷表!C:C,A3) -> 67 | C3: =SUMIF(病歷表!$C$2:$C$200,A3,病歷表!$B$2:$B$200) -> 1258
A4: {=IFERROR(INDEX(病歷表!$C$2:$C$3416, MATCH(0, COUNTIF($A$1:A3, 病歷表!$C$2:$C$3416), 0)), "")} -> SCC | B4: =COUNTIF(病歷表!C:C,A4) -> 29 | C4: =SUMIF(病歷表!$C$2:$C$200,A4,病歷表!$B$2:$B$200) -> 368
B5: =SUM(B2:B4) -> 143 | C5: =SUM(C2:C4) -> 2067

Sheet 無分類
A2: =ROW()-1 -> 1 | B2: img0000000406_normal.jpg | C2: 其他
A3: =ROW()-1 -> 2 | B3: img0000000407_normal.jpg | C3: 其他
A4: =ROW()-1 -> 3 | B4: img0000000410_normal.jpg | C4: 其他
A5: =ROW()-1 -> 4 | B5: img0000000605_normal.jpg | C5: 其他
A6: =ROW()-1 -> 5 | B6: img0000000645_normal.jpg | C6: 其他
A7: =ROW()-1 -> 6 | B7: img0000000755_normal.jpg | C7: 其他
A8: =ROW()-1 -> 7 | B8: img0000000761_normal.jpg | C8: 其他
A9: =ROW()-1 -> 8 | B9: img0000000800_normal.jpg | C9: 其他
A10: =ROW()-1 -> 9 | B10: img0000000801_normal.jpg | C10: 其他
A11: =ROW()-1 -> 10 | B11: img0000000802_normal.jpg | C11: 其他
A12: =ROW()-1 -> 11 | B12: img0000000804_normal.jpg | C12: 其他
A13: =ROW()-1 -> 12 | B13: img0000000805_normal.jpg | C13: 其他
... A180: =ROW()-1 -> 179 | B180: img0010849063_normal.jpg | C180: 其他
A181: =ROW()-1 -> 180 | B181: REC20220510-172051659__000067.jpg | C181: 其他 | D181: 20220510-20220905_KMUH
A182: =ROW()-1 -> 181 | B182: REC20220510-172051659__000077.jpg | C182: 其他
A183: =ROW()-1 -> 182 | B183: REC20220510-172051659__000085.jpg | C183: 其他
A184: =ROW()-1 -> 183 | B184: REC20220510-172051659__000485.jpg | C184: 其他
A185: =ROW()-1 -> 184 | B185: REC20220510-172051659__000495.jpg | C185: 其他
A186: =ROW()-1 -> 185 | B186: REC20220510-172051659__000497.jpg | C186: 其他
A187: =ROW()-1 -> 186 | B187: REC20220510-172051659__000501.jpg | C187: 其他
A188: =ROW()-1 -> 187 | B188: REC20220510-172051659__001635.jpg | C188: 其他
A189: =ROW()-1 -> 188 | B189: REC20220510-172051659__006927.jpg | C189: 其他
A190: =ROW()-1 -> 189 | B190: REC20220510-172051659__006937.jpg | C190: 其他
A191: =ROW()-1 -> 190 | B191: REC20220510-172051659__006945.jpg | C191: 其他
A192: =ROW()-1 -> 191 | B192: REC20220510-172051659__006951.jpg | C192: 其他
A193: =ROW()-1 -> 192 | B193: REC20220510-172051659__007011.jpg | C193: 其他
A194: =ROW()-1 -> 193 | B194: REC20220524-111408864__000005.jpg | C194: 其他 | D194: 20220510-20220905_KMUH
A195: =ROW()-1 -> 194 | B195: REC20220524-111408864__000021.jpg | C195: 其他
A196: =ROW()-1 -> 195 | B196: REC20220524-111408864__000025.jpg | C196: 其他
A197: =ROW()-1 -> 196 | B197: REC20220524-111408864__000027.jpg | C197: 其他
A198: =ROW()-1 -> 197 | B198: REC20220524-111408864__000031.jpg | C198: 其他
A199: =ROW()-1 -> 198 | B199: REC20220524-111408864__000035.jpg | C199: 其他
A200: =ROW()-1 -> 199 | B200: REC20220524-111408864__000381.jpg | C200: 其他
A201: =ROW()-1 -> 200 | B201: REC20220524-111408864__000405.jpg | C201: 其他
A202: =ROW()-1 -> 201 | B202: REC20220524-111408864__000447.jpg | C202: 其他
A203: =ROW()-1 -> 202 | B203: REC20220524-111408864__000461.jpg | C203: 其他
A204: =ROW()-1 -> 203 | B204: REC20220524-111408864__000465.jpg | C204: 其他
A205: =ROW()-1 -> 204 | B205: REC20220524-111408864__000477.jpg | C205: 其他
A206: =ROW()-1 -> 205 | B206: REC20220524-111408864__000481.jpg | C206: 其他
... A236: =ROW()-1 -> 235 | B236: REC20220524-111408864__006431.jpg | C236: 其他
...
